2020-05-17 09:47:10,763 ERROR: Exception on /edit_profile [POST] [in c:\users\jcumm\documents\12-microblog\microblog\venv\lib\site-packages\flask\app.py:1892]
Traceback (most recent call last):
  File "c:\users\jcumm\documents\12-microblog\microblog\venv\lib\site-packages\flask\app.py", line 2447, in wsgi_app
    response = self.full_dispatch_request()
  File "c:\users\jcumm\documents\12-microblog\microblog\venv\lib\site-packages\flask\app.py", line 1952, in full_dispatch_request
    rv = self.handle_user_exception(e)
  File "c:\users\jcumm\documents\12-microblog\microblog\venv\lib\site-packages\flask\app.py", line 1821, in handle_user_exception
    reraise(exc_type, exc_value, tb)
  File "c:\users\jcumm\documents\12-microblog\microblog\venv\lib\site-packages\flask\_compat.py", line 39, in reraise
    raise value
  File "c:\users\jcumm\documents\12-microblog\microblog\venv\lib\site-packages\flask\app.py", line 1950, in full_dispatch_request
    rv = self.dispatch_request()
  File "c:\users\jcumm\documents\12-microblog\microblog\venv\lib\site-packages\flask\app.py", line 1936, in dispatch_request
    return self.view_functions[rule.endpoint](**req.view_args)
  File "c:\users\jcumm\documents\12-microblog\microblog\venv\lib\site-packages\flask_login\utils.py", line 272, in decorated_view
    return func(*args, **kwargs)
  File "C:\Users\jcumm\Documents\12-microblog\microblog\app\routes.py", line 81, in edit_profile
    if form.validate_on_submit():
  File "c:\users\jcumm\documents\12-microblog\microblog\venv\lib\site-packages\flask_wtf\form.py", line 100, in validate_on_submit
    return self.is_submitted() and self.validate()
  File "c:\users\jcumm\documents\12-microblog\microblog\venv\lib\site-packages\wtforms\form.py", line 318, in validate
    return super(Form, self).validate(extra)
  File "c:\users\jcumm\documents\12-microblog\microblog\venv\lib\site-packages\wtforms\form.py", line 150, in validate
    if not field.validate(self, extra):
  File "c:\users\jcumm\documents\12-microblog\microblog\venv\lib\site-packages\wtforms\fields\core.py", line 226, in validate
    stop_validation = self._run_validation_chain(form, chain)
  File "c:\users\jcumm\documents\12-microblog\microblog\venv\lib\site-packages\wtforms\fields\core.py", line 246, in _run_validation_chain
    validator(form, self)
  File "C:\Users\jcumm\Documents\12-microblog\microblog\app\forms.py", line 43, in validate_username
    user = User.query.fitler_by(username=self.username.data).first()
AttributeError: 'BaseQuery' object has no attribute 'fitler_by'
2020-05-17 09:49:50,514 INFO: Microblog startup [in C:\Users\jcumm\Documents\12-microblog\microblog\app\__init__.py:45]
