2020-05-17 09:32:16,139 INFO: Microblog startup [in C:\Users\jcumm\Documents\12-microblog\microblog\app\__init__.py:45]
2020-05-17 09:32:28,648 ERROR: Exception on /edit_profile [POST] [in c:\users\jcumm\documents\12-microblog\microblog\venv\lib\site-packages\flask\app.py:1892]
Traceback (most recent call last):
  File "c:\users\jcumm\documents\12-microblog\microblog\venv\lib\site-packages\sqlalchemy\engine\base.py", line 1248, in _execute_context
    cursor, statement, parameters, context
  File "c:\users\jcumm\documents\12-microblog\microblog\venv\lib\site-packages\sqlalchemy\engine\default.py", line 590, in do_execute
    cursor.execute(statement, parameters)
sqlite3.IntegrityError: UNIQUE constraint failed: user.username

The above exception was the direct cause of the following exception:

Traceback (most recent call last):
  File "c:\users\jcumm\documents\12-microblog\microblog\venv\lib\site-packages\flask\app.py", line 2447, in wsgi_app
    response = self.full_dispatch_request()
  File "c:\users\jcumm\documents\12-microblog\microblog\venv\lib\site-packages\flask\app.py", line 1952, in full_dispatch_request
    rv = self.handle_user_exception(e)
  File "c:\users\jcumm\documents\12-microblog\microblog\venv\lib\site-packages\flask\app.py", line 1821, in handle_user_exception
    reraise(exc_type, exc_value, tb)
  File "c:\users\jcumm\documents\12-microblog\microblog\venv\lib\site-packages\flask\_compat.py", line 39, in reraise
    raise value
  File "c:\users\jcumm\documents\12-microblog\microblog\venv\lib\site-packages\flask\app.py", line 1950, in full_dispatch_request
    rv = self.dispatch_request()
  File "c:\users\jcumm\documents\12-microblog\microblog\venv\lib\site-packages\flask\app.py", line 1936, in dispatch_request
    return self.view_functions[rule.endpoint](**req.view_args)
  File "c:\users\jcumm\documents\12-microblog\microblog\venv\lib\site-packages\flask_login\utils.py", line 272, in decorated_view
    return func(*args, **kwargs)
  File "C:\Users\jcumm\Documents\12-microblog\microblog\app\routes.py", line 84, in edit_profile
    db.session.commit()
  File "c:\users\jcumm\documents\12-microblog\microblog\venv\lib\site-packages\sqlalchemy\orm\scoping.py", line 162, in do
    return getattr(self.registry(), name)(*args, **kwargs)
  File "c:\users\jcumm\documents\12-microblog\microblog\venv\lib\site-packages\sqlalchemy\orm\session.py", line 1036, in commit
    self.transaction.commit()
  File "c:\users\jcumm\documents\12-microblog\microblog\venv\lib\site-packages\sqlalchemy\orm\session.py", line 503, in commit
    self._prepare_impl()
  File "c:\users\jcumm\documents\12-microblog\microblog\venv\lib\site-packages\sqlalchemy\orm\session.py", line 482, in _prepare_impl
    self.session.flush()
  File "c:\users\jcumm\documents\12-microblog\microblog\venv\lib\site-packages\sqlalchemy\orm\session.py", line 2496, in flush
    self._flush(objects)
  File "c:\users\jcumm\documents\12-microblog\microblog\venv\lib\site-packages\sqlalchemy\orm\session.py", line 2637, in _flush
    transaction.rollback(_capture_exception=True)
  File "c:\users\jcumm\documents\12-microblog\microblog\venv\lib\site-packages\sqlalchemy\util\langhelpers.py", line 69, in __exit__
    exc_value, with_traceback=exc_tb,
  File "c:\users\jcumm\documents\12-microblog\microblog\venv\lib\site-packages\sqlalchemy\util\compat.py", line 178, in raise_
    raise exception
  File "c:\users\jcumm\documents\12-microblog\microblog\venv\lib\site-packages\sqlalchemy\orm\session.py", line 2597, in _flush
    flush_context.execute()
  File "c:\users\jcumm\documents\12-microblog\microblog\venv\lib\site-packages\sqlalchemy\orm\unitofwork.py", line 422, in execute
    rec.execute(self)
  File "c:\users\jcumm\documents\12-microblog\microblog\venv\lib\site-packages\sqlalchemy\orm\unitofwork.py", line 589, in execute
    uow,
  File "c:\users\jcumm\documents\12-microblog\microblog\venv\lib\site-packages\sqlalchemy\orm\persistence.py", line 236, in save_obj
    update,
  File "c:\users\jcumm\documents\12-microblog\microblog\venv\lib\site-packages\sqlalchemy\orm\persistence.py", line 995, in _emit_update_statements
    statement, multiparams
  File "c:\users\jcumm\documents\12-microblog\microblog\venv\lib\site-packages\sqlalchemy\engine\base.py", line 984, in execute
    return meth(self, multiparams, params)
  File "c:\users\jcumm\documents\12-microblog\microblog\venv\lib\site-packages\sqlalchemy\sql\elements.py", line 293, in _execute_on_connection
    return connection._execute_clauseelement(self, multiparams, params)
  File "c:\users\jcumm\documents\12-microblog\microblog\venv\lib\site-packages\sqlalchemy\engine\base.py", line 1103, in _execute_clauseelement
    distilled_params,
  File "c:\users\jcumm\documents\12-microblog\microblog\venv\lib\site-packages\sqlalchemy\engine\base.py", line 1288, in _execute_context
    e, statement, parameters, cursor, context
  File "c:\users\jcumm\documents\12-microblog\microblog\venv\lib\site-packages\sqlalchemy\engine\base.py", line 1482, in _handle_dbapi_exception
    sqlalchemy_exception, with_traceback=exc_info[2], from_=e
  File "c:\users\jcumm\documents\12-microblog\microblog\venv\lib\site-packages\sqlalchemy\util\compat.py", line 178, in raise_
    raise exception
  File "c:\users\jcumm\documents\12-microblog\microblog\venv\lib\site-packages\sqlalchemy\engine\base.py", line 1248, in _execute_context
    cursor, statement, parameters, context
  File "c:\users\jcumm\documents\12-microblog\microblog\venv\lib\site-packages\sqlalchemy\engine\default.py", line 590, in do_execute
    cursor.execute(statement, parameters)
sqlalchemy.exc.IntegrityError: (sqlite3.IntegrityError) UNIQUE constraint failed: user.username
[SQL: UPDATE user SET username=?, about_me=? WHERE user.id = ?]
[parameters: ('buttman', '', 6)]
(Background on this error at: http://sqlalche.me/e/gkpj)
2020-05-17 09:46:43,459 INFO: Microblog startup [in C:\Users\jcumm\Documents\12-microblog\microblog\app\__init__.py:45]
2020-05-17 09:46:56,139 ERROR: Exception on /edit_profile [POST] [in c:\users\jcumm\documents\12-microblog\microblog\venv\lib\site-packages\flask\app.py:1892]
Traceback (most recent call last):
  File "c:\users\jcumm\documents\12-microblog\microblog\venv\lib\site-packages\flask\app.py", line 2447, in wsgi_app
    response = self.full_dispatch_request()
  File "c:\users\jcumm\documents\12-microblog\microblog\venv\lib\site-packages\flask\app.py", line 1952, in full_dispatch_request
    rv = self.handle_user_exception(e)
  File "c:\users\jcumm\documents\12-microblog\microblog\venv\lib\site-packages\flask\app.py", line 1821, in handle_user_exception
    reraise(exc_type, exc_value, tb)
  File "c:\users\jcumm\documents\12-microblog\microblog\venv\lib\site-packages\flask\_compat.py", line 39, in reraise
    raise value
  File "c:\users\jcumm\documents\12-microblog\microblog\venv\lib\site-packages\flask\app.py", line 1950, in full_dispatch_request
    rv = self.dispatch_request()
  File "c:\users\jcumm\documents\12-microblog\microblog\venv\lib\site-packages\flask\app.py", line 1936, in dispatch_request
    return self.view_functions[rule.endpoint](**req.view_args)
  File "c:\users\jcumm\documents\12-microblog\microblog\venv\lib\site-packages\flask_login\utils.py", line 272, in decorated_view
    return func(*args, **kwargs)
  File "C:\Users\jcumm\Documents\12-microblog\microblog\app\routes.py", line 81, in edit_profile
    if form.validate_on_submit():
  File "c:\users\jcumm\documents\12-microblog\microblog\venv\lib\site-packages\flask_wtf\form.py", line 100, in validate_on_submit
    return self.is_submitted() and self.validate()
  File "c:\users\jcumm\documents\12-microblog\microblog\venv\lib\site-packages\wtforms\form.py", line 318, in validate
    return super(Form, self).validate(extra)
  File "c:\users\jcumm\documents\12-microblog\microblog\venv\lib\site-packages\wtforms\form.py", line 150, in validate
    if not field.validate(self, extra):
  File "c:\users\jcumm\documents\12-microblog\microblog\venv\lib\site-packages\wtforms\fields\core.py", line 226, in validate
    stop_validation = self._run_validation_chain(form, chain)
  File "c:\users\jcumm\documents\12-microblog\microblog\venv\lib\site-packages\wtforms\fields\core.py", line 246, in _run_validation_chain
    validator(form, self)
  File "C:\Users\jcumm\Documents\12-microblog\microblog\app\forms.py", line 43, in validate_username
    user = User.query.fitler_by(username=self.username.data).first()
AttributeError: 'BaseQuery' object has no attribute 'fitler_by'
