2020-05-17 09:47:10,763 ERROR: Exception on /edit_profile [POST] [in c:\users\jcumm\documents\12-microblog\microblog\venv\lib\site-packages\flask\app.py:1892]
Traceback (most recent call last):
  File "c:\users\jcumm\documents\12-microblog\microblog\venv\lib\site-packages\flask\app.py", line 2447, in wsgi_app
    response = self.full_dispatch_request()
  File "c:\users\jcumm\documents\12-microblog\microblog\venv\lib\site-packages\flask\app.py", line 1952, in full_dispatch_request
    rv = self.handle_user_exception(e)
  File "c:\users\jcumm\documents\12-microblog\microblog\venv\lib\site-packages\flask\app.py", line 1821, in handle_user_exception
    reraise(exc_type, exc_value, tb)
  File "c:\users\jcumm\documents\12-microblog\microblog\venv\lib\site-packages\flask\_compat.py", line 39, in reraise
    raise value
  File "c:\users\jcumm\documents\12-microblog\microblog\venv\lib\site-packages\flask\app.py", line 1950, in full_dispatch_request
    rv = self.dispatch_request()
  File "c:\users\jcumm\documents\12-microblog\microblog\venv\lib\site-packages\flask\app.py", line 1936, in dispatch_request
    return self.view_functions[rule.endpoint](**req.view_args)
  File "c:\users\jcumm\documents\12-microblog\microblog\venv\lib\site-packages\flask_login\utils.py", line 272, in decorated_view
    return func(*args, **kwargs)
  File "C:\Users\jcumm\Documents\12-microblog\microblog\app\routes.py", line 81, in edit_profile
    if form.validate_on_submit():
  File "c:\users\jcumm\documents\12-microblog\microblog\venv\lib\site-packages\flask_wtf\form.py", line 100, in validate_on_submit
    return self.is_submitted() and self.validate()
  File "c:\users\jcumm\documents\12-microblog\microblog\venv\lib\site-packages\wtforms\form.py", line 318, in validate
    return super(Form, self).validate(extra)
  File "c:\users\jcumm\documents\12-microblog\microblog\venv\lib\site-packages\wtforms\form.py", line 150, in validate
    if not field.validate(self, extra):
  File "c:\users\jcumm\documents\12-microblog\microblog\venv\lib\site-packages\wtforms\fields\core.py", line 226, in validate
    stop_validation = self._run_validation_chain(form, chain)
  File "c:\users\jcumm\documents\12-microblog\microblog\venv\lib\site-packages\wtforms\fields\core.py", line 246, in _run_validation_chain
    validator(form, self)
  File "C:\Users\jcumm\Documents\12-microblog\microblog\app\forms.py", line 43, in validate_username
    user = User.query.fitler_by(username=self.username.data).first()
AttributeError: 'BaseQuery' object has no attribute 'fitler_by'
2020-05-17 09:49:50,514 INFO: Microblog startup [in C:\Users\jcumm\Documents\12-microblog\microblog\app\__init__.py:45]
2020-05-17 10:27:30,454 INFO: Microblog startup [in C:\Users\jcumm\Documents\12-microblog\microblog\app\__init__.py:45]
2020-05-17 10:27:41,167 INFO: Microblog startup [in C:\Users\jcumm\Documents\12-microblog\microblog\app\__init__.py:45]
2020-05-17 11:36:14,973 INFO: Microblog startup [in C:\Users\jcumm\Documents\12-microblog\microblog\app\__init__.py:45]
2020-05-17 11:36:27,447 INFO: Microblog startup [in C:\Users\jcumm\Documents\12-microblog\microblog\app\__init__.py:45]
2020-05-17 11:39:58,394 INFO: Microblog startup [in C:\Users\jcumm\Documents\12-microblog\microblog\app\__init__.py:45]
2020-05-17 11:44:45,428 INFO: Microblog startup [in C:\Users\jcumm\Documents\12-microblog\microblog\app\__init__.py:45]
2020-05-17 11:45:07,096 INFO: Microblog startup [in C:\Users\jcumm\Documents\12-microblog\microblog\app\__init__.py:45]
2020-05-17 11:45:32,881 INFO: Microblog startup [in C:\Users\jcumm\Documents\12-microblog\microblog\app\__init__.py:45]
2020-05-17 11:45:48,205 INFO: Microblog startup [in C:\Users\jcumm\Documents\12-microblog\microblog\app\__init__.py:45]
2020-05-17 12:03:38,333 INFO: Microblog startup [in C:\Users\jcumm\Documents\12-microblog\microblog\app\__init__.py:45]
2020-05-17 12:03:42,817 ERROR: Exception on /index [GET] [in c:\users\jcumm\documents\12-microblog\microblog\venv\lib\site-packages\flask\app.py:1892]
Traceback (most recent call last):
  File "c:\users\jcumm\documents\12-microblog\microblog\venv\lib\site-packages\sqlalchemy\engine\base.py", line 1248, in _execute_context
    cursor, statement, parameters, context
  File "c:\users\jcumm\documents\12-microblog\microblog\venv\lib\site-packages\sqlalchemy\engine\default.py", line 590, in do_execute
    cursor.execute(statement, parameters)
sqlite3.OperationalError: no such table: user

The above exception was the direct cause of the following exception:

Traceback (most recent call last):
  File "c:\users\jcumm\documents\12-microblog\microblog\venv\lib\site-packages\flask\app.py", line 2447, in wsgi_app
    response = self.full_dispatch_request()
  File "c:\users\jcumm\documents\12-microblog\microblog\venv\lib\site-packages\flask\app.py", line 1952, in full_dispatch_request
    rv = self.handle_user_exception(e)
  File "c:\users\jcumm\documents\12-microblog\microblog\venv\lib\site-packages\flask\app.py", line 1821, in handle_user_exception
    reraise(exc_type, exc_value, tb)
  File "c:\users\jcumm\documents\12-microblog\microblog\venv\lib\site-packages\flask\_compat.py", line 39, in reraise
    raise value
  File "c:\users\jcumm\documents\12-microblog\microblog\venv\lib\site-packages\flask\app.py", line 1948, in full_dispatch_request
    rv = self.preprocess_request()
  File "c:\users\jcumm\documents\12-microblog\microblog\venv\lib\site-packages\flask\app.py", line 2242, in preprocess_request
    rv = func()
  File "C:\Users\jcumm\Documents\12-microblog\microblog\app\routes.py", line 73, in before_request
    if current_user.is_authenticated:
  File "c:\users\jcumm\documents\12-microblog\microblog\venv\lib\site-packages\werkzeug\local.py", line 347, in __getattr__
    return getattr(self._get_current_object(), name)
  File "c:\users\jcumm\documents\12-microblog\microblog\venv\lib\site-packages\werkzeug\local.py", line 306, in _get_current_object
    return self.__local()
  File "c:\users\jcumm\documents\12-microblog\microblog\venv\lib\site-packages\flask_login\utils.py", line 26, in <lambda>
    current_user = LocalProxy(lambda: _get_user())
  File "c:\users\jcumm\documents\12-microblog\microblog\venv\lib\site-packages\flask_login\utils.py", line 346, in _get_user
    current_app.login_manager._load_user()
  File "c:\users\jcumm\documents\12-microblog\microblog\venv\lib\site-packages\flask_login\login_manager.py", line 318, in _load_user
    user = self._user_callback(user_id)
  File "C:\Users\jcumm\Documents\12-microblog\microblog\app\models.py", line 64, in load_user
    return User.query.get(int(id))
  File "c:\users\jcumm\documents\12-microblog\microblog\venv\lib\site-packages\sqlalchemy\orm\query.py", line 1004, in get
    return self._get_impl(ident, loading.load_on_pk_identity)
  File "c:\users\jcumm\documents\12-microblog\microblog\venv\lib\site-packages\sqlalchemy\orm\query.py", line 1121, in _get_impl
    return db_load_fn(self, primary_key_identity)
  File "c:\users\jcumm\documents\12-microblog\microblog\venv\lib\site-packages\sqlalchemy\orm\loading.py", line 287, in load_on_pk_identity
    return q.one()
  File "c:\users\jcumm\documents\12-microblog\microblog\venv\lib\site-packages\sqlalchemy\orm\query.py", line 3360, in one
    ret = self.one_or_none()
  File "c:\users\jcumm\documents\12-microblog\microblog\venv\lib\site-packages\sqlalchemy\orm\query.py", line 3329, in one_or_none
    ret = list(self)
  File "c:\users\jcumm\documents\12-microblog\microblog\venv\lib\site-packages\sqlalchemy\orm\query.py", line 3405, in __iter__
    return self._execute_and_instances(context)
  File "c:\users\jcumm\documents\12-microblog\microblog\venv\lib\site-packages\sqlalchemy\orm\query.py", line 3430, in _execute_and_instances
    result = conn.execute(querycontext.statement, self._params)
  File "c:\users\jcumm\documents\12-microblog\microblog\venv\lib\site-packages\sqlalchemy\engine\base.py", line 984, in execute
    return meth(self, multiparams, params)
  File "c:\users\jcumm\documents\12-microblog\microblog\venv\lib\site-packages\sqlalchemy\sql\elements.py", line 293, in _execute_on_connection
    return connection._execute_clauseelement(self, multiparams, params)
  File "c:\users\jcumm\documents\12-microblog\microblog\venv\lib\site-packages\sqlalchemy\engine\base.py", line 1103, in _execute_clauseelement
    distilled_params,
  File "c:\users\jcumm\documents\12-microblog\microblog\venv\lib\site-packages\sqlalchemy\engine\base.py", line 1288, in _execute_context
    e, statement, parameters, cursor, context
  File "c:\users\jcumm\documents\12-microblog\microblog\venv\lib\site-packages\sqlalchemy\engine\base.py", line 1482, in _handle_dbapi_exception
    sqlalchemy_exception, with_traceback=exc_info[2], from_=e
  File "c:\users\jcumm\documents\12-microblog\microblog\venv\lib\site-packages\sqlalchemy\util\compat.py", line 178, in raise_
    raise exception
  File "c:\users\jcumm\documents\12-microblog\microblog\venv\lib\site-packages\sqlalchemy\engine\base.py", line 1248, in _execute_context
    cursor, statement, parameters, context
  File "c:\users\jcumm\documents\12-microblog\microblog\venv\lib\site-packages\sqlalchemy\engine\default.py", line 590, in do_execute
    cursor.execute(statement, parameters)
sqlalchemy.exc.OperationalError: (sqlite3.OperationalError) no such table: user
[SQL: SELECT user.id AS user_id, user.username AS user_username, user.email AS user_email, user.password_hash AS user_password_hash, user.about_me AS user_about_me, user.last_seen AS user_last_seen 
FROM user 
WHERE user.id = ?]
[parameters: (6,)]
(Background on this error at: http://sqlalche.me/e/e3q8)
2020-05-17 12:05:32,098 INFO: Microblog startup [in C:\Users\jcumm\Documents\12-microblog\microblog\app\__init__.py:45]
