2020-05-17 12:11:06,664 ERROR: Exception on /user/susan [GET] [in c:\users\jcumm\documents\12-microblog\microblog\venv\lib\site-packages\flask\app.py:1892]
Traceback (most recent call last):
  File "c:\users\jcumm\documents\12-microblog\microblog\venv\lib\site-packages\sqlalchemy\engine\base.py", line 1248, in _execute_context
    cursor, statement, parameters, context
  File "c:\users\jcumm\documents\12-microblog\microblog\venv\lib\site-packages\sqlalchemy\engine\default.py", line 590, in do_execute
    cursor.execute(statement, parameters)
sqlite3.OperationalError: no such table: user

The above exception was the direct cause of the following exception:

Traceback (most recent call last):
  File "c:\users\jcumm\documents\12-microblog\microblog\venv\lib\site-packages\flask\app.py", line 2447, in wsgi_app
    response = self.full_dispatch_request()
  File "c:\users\jcumm\documents\12-microblog\microblog\venv\lib\site-packages\flask\app.py", line 1952, in full_dispatch_request
    rv = self.handle_user_exception(e)
  File "c:\users\jcumm\documents\12-microblog\microblog\venv\lib\site-packages\flask\app.py", line 1821, in handle_user_exception
    reraise(exc_type, exc_value, tb)
  File "c:\users\jcumm\documents\12-microblog\microblog\venv\lib\site-packages\flask\_compat.py", line 39, in reraise
    raise value
  File "c:\users\jcumm\documents\12-microblog\microblog\venv\lib\site-packages\flask\app.py", line 1948, in full_dispatch_request
    rv = self.preprocess_request()
  File "c:\users\jcumm\documents\12-microblog\microblog\venv\lib\site-packages\flask\app.py", line 2242, in preprocess_request
    rv = func()
  File "C:\Users\jcumm\Documents\12-microblog\microblog\app\routes.py", line 73, in before_request
    if current_user.is_authenticated:
  File "c:\users\jcumm\documents\12-microblog\microblog\venv\lib\site-packages\werkzeug\local.py", line 347, in __getattr__
    return getattr(self._get_current_object(), name)
  File "c:\users\jcumm\documents\12-microblog\microblog\venv\lib\site-packages\werkzeug\local.py", line 306, in _get_current_object
    return self.__local()
  File "c:\users\jcumm\documents\12-microblog\microblog\venv\lib\site-packages\flask_login\utils.py", line 26, in <lambda>
    current_user = LocalProxy(lambda: _get_user())
  File "c:\users\jcumm\documents\12-microblog\microblog\venv\lib\site-packages\flask_login\utils.py", line 346, in _get_user
    current_app.login_manager._load_user()
  File "c:\users\jcumm\documents\12-microblog\microblog\venv\lib\site-packages\flask_login\login_manager.py", line 318, in _load_user
    user = self._user_callback(user_id)
  File "C:\Users\jcumm\Documents\12-microblog\microblog\app\models.py", line 64, in load_user
    return User.query.get(int(id))
  File "c:\users\jcumm\documents\12-microblog\microblog\venv\lib\site-packages\sqlalchemy\orm\query.py", line 1004, in get
    return self._get_impl(ident, loading.load_on_pk_identity)
  File "c:\users\jcumm\documents\12-microblog\microblog\venv\lib\site-packages\sqlalchemy\orm\query.py", line 1121, in _get_impl
    return db_load_fn(self, primary_key_identity)
  File "c:\users\jcumm\documents\12-microblog\microblog\venv\lib\site-packages\sqlalchemy\orm\loading.py", line 287, in load_on_pk_identity
    return q.one()
  File "c:\users\jcumm\documents\12-microblog\microblog\venv\lib\site-packages\sqlalchemy\orm\query.py", line 3360, in one
    ret = self.one_or_none()
  File "c:\users\jcumm\documents\12-microblog\microblog\venv\lib\site-packages\sqlalchemy\orm\query.py", line 3329, in one_or_none
    ret = list(self)
  File "c:\users\jcumm\documents\12-microblog\microblog\venv\lib\site-packages\sqlalchemy\orm\query.py", line 3405, in __iter__
    return self._execute_and_instances(context)
  File "c:\users\jcumm\documents\12-microblog\microblog\venv\lib\site-packages\sqlalchemy\orm\query.py", line 3430, in _execute_and_instances
    result = conn.execute(querycontext.statement, self._params)
  File "c:\users\jcumm\documents\12-microblog\microblog\venv\lib\site-packages\sqlalchemy\engine\base.py", line 984, in execute
    return meth(self, multiparams, params)
  File "c:\users\jcumm\documents\12-microblog\microblog\venv\lib\site-packages\sqlalchemy\sql\elements.py", line 293, in _execute_on_connection
    return connection._execute_clauseelement(self, multiparams, params)
  File "c:\users\jcumm\documents\12-microblog\microblog\venv\lib\site-packages\sqlalchemy\engine\base.py", line 1103, in _execute_clauseelement
    distilled_params,
  File "c:\users\jcumm\documents\12-microblog\microblog\venv\lib\site-packages\sqlalchemy\engine\base.py", line 1288, in _execute_context
    e, statement, parameters, cursor, context
  File "c:\users\jcumm\documents\12-microblog\microblog\venv\lib\site-packages\sqlalchemy\engine\base.py", line 1482, in _handle_dbapi_exception
    sqlalchemy_exception, with_traceback=exc_info[2], from_=e
  File "c:\users\jcumm\documents\12-microblog\microblog\venv\lib\site-packages\sqlalchemy\util\compat.py", line 178, in raise_
    raise exception
  File "c:\users\jcumm\documents\12-microblog\microblog\venv\lib\site-packages\sqlalchemy\engine\base.py", line 1248, in _execute_context
    cursor, statement, parameters, context
  File "c:\users\jcumm\documents\12-microblog\microblog\venv\lib\site-packages\sqlalchemy\engine\default.py", line 590, in do_execute
    cursor.execute(statement, parameters)
sqlalchemy.exc.OperationalError: (sqlite3.OperationalError) no such table: user
[SQL: SELECT user.id AS user_id, user.username AS user_username, user.email AS user_email, user.password_hash AS user_password_hash, user.about_me AS user_about_me, user.last_seen AS user_last_seen 
FROM user 
WHERE user.id = ?]
[parameters: (6,)]
(Background on this error at: http://sqlalche.me/e/e3q8)
2020-05-17 12:14:29,545 INFO: Microblog startup [in C:\Users\jcumm\Documents\12-microblog\microblog\app\__init__.py:45]
2020-05-17 12:16:53,793 INFO: Microblog startup [in C:\Users\jcumm\Documents\12-microblog\microblog\app\__init__.py:45]
